{
 "cells": [
  {
   "cell_type": "markdown",
   "id": "69d822ae",
   "metadata": {},
   "source": [
    "## 1. Describe three applications for exception processing."
   ]
  },
  {
   "cell_type": "markdown",
   "id": "8393e3e7",
   "metadata": {},
   "source": [
    "Exception processing is a fundamental aspect of error handling in programming languages, including Python. Here are three common applications for exception processing:\n",
    "\n",
    "1. Error handling and recovery: Exception processing allows you to handle errors and exceptions that may occur during the execution of your code. By using try-except blocks, you can catch specific exceptions and gracefully handle them, preventing the program from crashing or displaying cryptic error messages. Error handling can involve logging the error, displaying user-friendly error messages, or performing specific actions to recover from the error and continue program execution.\n",
    "\n",
    "```python\n",
    "try:\n",
    "    # Code that may raise an exception\n",
    "    result = divide(10, 0)\n",
    "    print(\"Result:\", result)\n",
    "except ZeroDivisionError:\n",
    "    print(\"Error: Division by zero\")\n",
    "    # Perform error recovery or alternative action\n",
    "    result = handle_error()\n",
    "    print(\"Recovered result:\", result)\n",
    "```\n",
    "\n",
    "In this example, an exception of type `ZeroDivisionError` may occur if the division by zero operation fails. The exception is caught in the `except` block, allowing you to handle it gracefully. You can display an error message, perform recovery actions, and continue program execution.\n",
    "\n",
    "2. Input validation and user interaction: Exception processing is often used for input validation, where you can catch and handle exceptions when the user provides invalid or unexpected input. By validating user input within a try-except block, you can prompt the user for correct input, display informative messages, or guide them through the process of providing valid input.\n",
    "\n",
    "```python\n",
    "try:\n",
    "    age = int(input(\"Enter your age: \"))\n",
    "except ValueError:\n",
    "    print(\"Invalid input: Please enter a valid integer for age.\")\n",
    "    # Prompt the user again for correct input\n",
    "    age = int(input(\"Enter your age: \"))\n",
    "```\n",
    "\n",
    "In this example, the `int()` function is used to convert user input to an integer. If the user enters invalid input (such as a non-numeric value), a `ValueError` exception is raised. The exception is caught in the `except` block, allowing you to display an error message and prompt the user for valid input.\n",
    "\n",
    "3. Resource management and cleanup: Exception processing is also crucial for managing and cleaning up resources such as files, database connections, or network sockets. By using try-finally or try-except-finally blocks, you can ensure that resources are properly released or cleaned up, even if an exception occurs during their usage.\n",
    "\n",
    "```python\n",
    "file = None\n",
    "try:\n",
    "    file = open(\"data.txt\", \"r\")\n",
    "    # Code that reads data from the file\n",
    "    data = file.read()\n",
    "    print(\"Data:\", data)\n",
    "except FileNotFoundError:\n",
    "    print(\"Error: File not found\")\n",
    "finally:\n",
    "    # Ensure the file is always closed, even if an exception occurred\n",
    "    if file:\n",
    "        file.close()\n",
    "```\n",
    "\n",
    "In this example, a file is opened for reading. If the file is not found (`FileNotFoundError`), an exception is caught in the `except` block, and an error message is displayed. The `finally` block ensures that the file is always closed, regardless of whether an exception occurred or not.\n",
    "\n",
    "Exception processing plays a vital role in error handling, input validation, and resource management. It allows you to handle errors gracefully, validate input, and ensure proper cleanup of resources, leading to more robust and reliable programs."
   ]
  },
  {
   "cell_type": "markdown",
   "id": "39086045",
   "metadata": {},
   "source": [
    "## 2. What happens if you don&#39;t do something extra to treat an exception?"
   ]
  },
  {
   "cell_type": "markdown",
   "id": "a10ee135",
   "metadata": {},
   "source": [
    "If you don't handle an exception in your code, either by catching it or allowing it to propagate, the unhandled exception will result in the termination of your program. When an exception occurs and is not appropriately handled, Python displays an error message traceback and exits the program abruptly.\n",
    "\n",
    "Here's what happens when an exception is left unhandled:\n",
    "\n",
    "1. Error message traceback: When an exception occurs, Python prints a traceback message that provides information about the exception type, the line of code where it occurred, and the sequence of calls leading to the exception. This traceback message helps in diagnosing and debugging the error.\n",
    "\n",
    "2. Program termination: After displaying the traceback message, Python terminates the program's execution. This means that any remaining code after the unhandled exception will not be executed, and the program comes to an abrupt halt.\n",
    "\n",
    "3. Resource cleanup: Unhandled exceptions may prevent proper cleanup of resources, such as open files, network connections, or database connections. When the program terminates unexpectedly, these resources may not be released or closed properly, potentially leading to resource leaks or inconsistencies.\n",
    "\n",
    "To illustrate the consequences of an unhandled exception, consider the following example:\n",
    "\n",
    "```python\n",
    "def divide(a, b):\n",
    "    result = a / b\n",
    "    return result\n",
    "\n",
    "num1 = 10\n",
    "num2 = 0\n",
    "\n",
    "result = divide(num1, num2)\n",
    "print(\"Result:\", result)\n",
    "```\n",
    "\n",
    "In this example, the `divide` function attempts to divide `num1` by `num2`, which will raise a `ZeroDivisionError` exception. If the exception is left unhandled, the program will display an error traceback message indicating the division by zero error, and the program will terminate. The final print statement will not be executed.\n",
    "\n",
    "By not handling the exception, you miss the opportunity to gracefully recover from the error, provide alternative behavior, or perform any necessary cleanup actions. It's important to handle exceptions appropriately to ensure your program behaves as intended, maintains stability, and avoids unexpected termination.\n",
    "\n",
    "To handle exceptions, you can use `try-except` blocks to catch specific exceptions, perform error recovery, display meaningful error messages, or log errors for debugging purposes. Handling exceptions allows your program to gracefully respond to errors and continue executing code without terminating abruptly."
   ]
  },
  {
   "cell_type": "markdown",
   "id": "1197114f",
   "metadata": {},
   "source": [
    "## 3. What are your options for recovering from an exception in your script?"
   ]
  },
  {
   "cell_type": "markdown",
   "id": "db8e974f",
   "metadata": {},
   "source": [
    "When an exception occurs in your script, you have several options for recovering from it and continuing the execution of your code. Here are some common approaches:\n",
    "\n",
    "1. Catch and handle the exception: You can use a `try-except` block to catch the specific exception that occurred and handle it gracefully. Within the `except` block, you can perform error recovery actions, display informative error messages, or prompt the user for alternative input. By handling the exception, you prevent the program from crashing and allow it to continue executing.\n",
    "\n",
    "```python\n",
    "try:\n",
    "    # Code that may raise an exception\n",
    "    result = divide(10, 0)\n",
    "    print(\"Result:\", result)\n",
    "except ZeroDivisionError:\n",
    "    print(\"Error: Division by zero\")\n",
    "    # Perform error recovery or alternative action\n",
    "    result = handle_error()\n",
    "    print(\"Recovered result:\", result)\n",
    "```\n",
    "\n",
    "In this example, the `ZeroDivisionError` exception is caught in the `except` block, and error recovery actions are performed, allowing the program to continue execution.\n",
    "\n",
    "2. Retry the operation: If the exception is recoverable, you can implement a retry mechanism to attempt the operation again. By placing the problematic code within a loop, you can catch the exception, wait for a certain period, and then retry the operation. This approach is useful for handling transient errors or situations where the initial attempt failed due to temporary conditions.\n",
    "\n",
    "```python\n",
    "max_retries = 3\n",
    "retry_delay = 1  # seconds\n",
    "\n",
    "for attempt in range(max_retries):\n",
    "    try:\n",
    "        # Code that may raise an exception\n",
    "        result = perform_operation()\n",
    "        break  # Break out of the loop if successful\n",
    "    except Exception as e:\n",
    "        print(\"Error:\", str(e))\n",
    "        print(\"Retrying in\", retry_delay, \"seconds...\")\n",
    "        time.sleep(retry_delay)\n",
    "else:\n",
    "    print(\"Operation failed after\", max_retries, \"attempts\")\n",
    "```\n",
    "\n",
    "In this example, the code within the `try` block is attempted multiple times within the loop. If an exception occurs, the error is printed, and the loop waits for a specified delay before retrying the operation. If the maximum number of retries is reached, the script outputs a failure message.\n",
    "\n",
    "3. Provide default values or fallback behavior: If an exception occurs during a specific operation, you can handle it by providing default values or fallback behavior. This approach allows the script to continue executing with alternative data or behavior, ensuring that subsequent operations are not disrupted.\n",
    "\n",
    "```python\n",
    "try:\n",
    "    # Code that may raise an exception\n",
    "    result = perform_operation()\n",
    "except SomeException:\n",
    "    print(\"Error: SomeException occurred\")\n",
    "    # Provide default value or fallback behavior\n",
    "    result = default_value\n",
    "```\n",
    "\n",
    "In this example, if an exception of type `SomeException` occurs during the `perform_operation()` call, the script catches the exception, displays an error message, and assigns a default value to `result`. This ensures that the subsequent code can continue executing without relying on the failed operation's result.\n",
    "\n",
    "4. Log the exception: Instead of directly recovering from the exception, you can choose to log the exception details for debugging purposes. Logging the exception allows you to capture information about the error, such as the stack trace, error message, and relevant data, which can help in diagnosing and troubleshooting issues.\n",
    "\n",
    "```python\n",
    "try:\n",
    "    # Code that may raise an exception\n",
    "    result = perform_operation()\n",
    "except Exception as e:\n",
    "    # Log the exception for debugging\n",
    "    logger.error(\"Exception occurred: %s\", str(e))\n",
    "    # Optionally re-raise the exception to propagate it\n",
    "    raise\n",
    "```\n",
    "\n",
    "In this example, the exception is caught, and the details are logged using a logging framework. The `logger.error()` call records the exception information, enabling you to analyze it later. You can also choose to re-raise the exception using `raise` if you want it to propagate further up the call stack.\n",
    "\n",
    "These are just a few options for recovering from exceptions in your script. The approach you choose depends on the specific scenario, the nature of the exception, and the desired behavior for your application. Handling exceptions appropriately allows your script to gracefully respond to errors and continue executing, ensuring robustness and maintaining a positive user experience."
   ]
  },
  {
   "cell_type": "markdown",
   "id": "0b6e472f",
   "metadata": {},
   "source": [
    "## 4. Describe two methods for triggering exceptions in your script."
   ]
  },
  {
   "cell_type": "markdown",
   "id": "abf3fc07",
   "metadata": {},
   "source": [
    "In Python, there are various methods for triggering exceptions intentionally in your script. Here are two commonly used methods:\n",
    "\n",
    "1. Raise an exception explicitly: You can raise an exception explicitly using the `raise` statement. This allows you to generate and trigger an exception of a specific type with a custom error message or additional information. By raising an exception, you can control the flow of your program and signal that a certain condition or situation has occurred.\n",
    "\n",
    "```python\n",
    "def divide(a, b):\n",
    "    if b == 0:\n",
    "        raise ZeroDivisionError(\"Division by zero is not allowed.\")\n",
    "    return a / b\n",
    "\n",
    "try:\n",
    "    result = divide(10, 0)\n",
    "    print(\"Result:\", result)\n",
    "except ZeroDivisionError as e:\n",
    "    print(\"Error:\", str(e))\n",
    "```\n",
    "\n",
    "In this example, the `divide` function raises a `ZeroDivisionError` exception explicitly when the `b` parameter is equal to 0. The exception includes a custom error message. When the exception is raised, it is caught in the `except` block, and the error message is displayed.\n",
    "\n",
    "2. Use built-in functions or operations that raise exceptions: Certain built-in functions or operations in Python can raise exceptions in specific scenarios. By using these functions or operations, you can trigger exceptions based on the predefined conditions they check.\n",
    "\n",
    "For example, the `int()` function raises a `ValueError` exception if it fails to convert a string to an integer:\n",
    "\n",
    "```python\n",
    "user_input = \"abc\"\n",
    "try:\n",
    "    number = int(user_input)\n",
    "    print(\"Number:\", number)\n",
    "except ValueError:\n",
    "    print(\"Invalid input: Please enter a valid integer.\")\n",
    "```\n",
    "\n",
    "In this example, if the user enters a non-numeric string, such as `\"abc\"`, the `int()` function fails to convert it to an integer and raises a `ValueError` exception. The exception is caught in the `except` block, and an appropriate error message is displayed.\n",
    "\n",
    "Similarly, performing operations like accessing elements outside the bounds of a list or index, dividing by zero, or attempting to open a non-existent file can trigger exceptions like `IndexError`, `ZeroDivisionError`, or `FileNotFoundError`, respectively.\n",
    "\n",
    "By intentionally triggering exceptions in your script, you can handle specific scenarios, validate input, enforce certain conditions, or respond to exceptional situations with custom error handling logic. It allows you to gracefully handle errors and provide appropriate feedback to users or take corrective actions as needed."
   ]
  },
  {
   "cell_type": "markdown",
   "id": "ef22e983",
   "metadata": {},
   "source": [
    "## 5. Identify two methods for specifying actions to be executed at termination time, regardless of whether or not an exception exists."
   ]
  },
  {
   "cell_type": "markdown",
   "id": "9285177a",
   "metadata": {},
   "source": [
    "In Python, you can specify actions to be executed at termination time, regardless of whether or not an exception exists, by using two methods:\n",
    "\n",
    "1. Using the `finally` block: The `finally` block is a construct that allows you to specify a set of statements that will always be executed, regardless of whether an exception occurred or not. The code inside the `finally` block is executed after the try-except block, ensuring that it is executed even if an exception is raised or caught.\n",
    "\n",
    "```python\n",
    "try:\n",
    "    # Code that may raise an exception\n",
    "    file = open(\"data.txt\", \"r\")\n",
    "    # Code that operates on the file\n",
    "except FileNotFoundError:\n",
    "    print(\"File not found\")\n",
    "finally:\n",
    "    # Code that always executes, regardless of exception\n",
    "    file.close()\n",
    "    print(\"File closed\")\n",
    "```\n",
    "\n",
    "In this example, the `finally` block is used to ensure that the file opened in the `try` block is closed, regardless of whether a `FileNotFoundError` exception occurs or not. The code inside the `finally` block will always be executed, providing a reliable way to clean up resources or perform essential actions.\n",
    "\n",
    "2. Using the `atexit` module: The `atexit` module provides a way to register functions or methods that will be executed when the Python interpreter is about to exit, regardless of whether an exception occurred or not. These registered functions are executed in reverse order of registration.\n",
    "\n",
    "```python\n",
    "import atexit\n",
    "\n",
    "def cleanup():\n",
    "    print(\"Performing cleanup operations\")\n",
    "\n",
    "atexit.register(cleanup)\n",
    "\n",
    "# Code that may raise an exception\n",
    "result = divide(10, 0)\n",
    "print(\"Result:\", result)\n",
    "```\n",
    "\n",
    "In this example, the `cleanup` function is registered using the `atexit.register()` function. This function ensures that the `cleanup` function will be called when the script is about to exit, regardless of whether an exception occurs or not. The function can perform necessary cleanup operations, such as closing files, releasing resources, or logging final messages.\n",
    "\n",
    "By using the `finally` block or the `atexit` module, you can specify actions that should be executed at termination time, irrespective of whether an exception occurred or not. These methods allow you to ensure the proper cleanup of resources, perform final operations, or log important information before the script exits, providing a way to gracefully terminate the program and maintain the integrity of your code."
   ]
  }
 ],
 "metadata": {
  "kernelspec": {
   "display_name": "Python 3 (ipykernel)",
   "language": "python",
   "name": "python3"
  },
  "language_info": {
   "codemirror_mode": {
    "name": "ipython",
    "version": 3
   },
   "file_extension": ".py",
   "mimetype": "text/x-python",
   "name": "python",
   "nbconvert_exporter": "python",
   "pygments_lexer": "ipython3",
   "version": "3.9.13"
  }
 },
 "nbformat": 4,
 "nbformat_minor": 5
}
